<mujoco model="crane_x7">
  <option iterations="50" timestep="0.001" solver="PGS" gravity="0 0 -9.81" />

  <compiler angle="radian" meshdir="meshes" eulerseq="zyx" autolimits="true" />

  <default>
    <joint limited="true" damping="0.01" armature="0.01" frictionloss="0.01" />
    <geom condim="4" contype="1" conaffinity="15" friction="0.9 0.2 0.2" solref="0.001 2" />
    <motor ctrllimited="true" />
    <equality solref="0.001 2" />
    <default class="visualgeom">
      <geom material="visualgeom" condim="1" contype="0" conaffinity="0" />
    </default>
  </default>

  <asset>
    <mesh name="mounting_plate" file="mounting_plate.stl" />
    <mesh name="base_fixed_part" file="base_fixed_part.stl" />
    <mesh name="rotating_link_type_1_fixed_part" file="rotating_link_type_1_fixed_part.stl" />
    <mesh name="joint_cover" file="joint_cover.stl" />
    <mesh name="rotating_link_type_1_revolute_part" file="rotating_link_type_1_revolute_part.stl" />
    <mesh name="rotating_link_type_2_fixed_part" file="rotating_link_type_2_fixed_part.stl" />
    <mesh name="rotating_link_type_2_revolute_part" file="rotating_link_type_2_revolute_part.stl" />
    <mesh name="rtcorp_logo_name" file="rtcorp_logo_name.stl" />
    <mesh name="rtcorp_logo_rabbit" file="rtcorp_logo_rabbit.stl" />
    <mesh name="wrist" file="wrist.stl" />
    <mesh name="wide_two_finger_gripper_actuator" file="wide_two_finger_gripper_actuator.stl" />
    <mesh name="wide_two_finger_gripper_finger_a" file="wide_two_finger_gripper_finger_a.stl" />
    <mesh name="wide_two_finger_gripper_finger_b" file="wide_two_finger_gripper_finger_b.stl" />
    <texture name="texplane" type="2d" builtin="checker" rgb1=".0 .0 .0" rgb2=".8 .8 .8" width="100" height="100" />
    <material name="matplane" reflectance="0." texture="texplane" texrepeat="1 1" texuniform="true" />
    <material name="visualgeom" rgba="0.5 0.9 0.2 1" />
  </asset>

  <worldbody>
    <light directional="true" diffuse="0.4 0.4 0.4" specular="0.1 0.1 0.1" pos="0 0 5.0" dir="0 0 -1" castshadow="false" />
    <light directional="true" diffuse="0.6 0.6 0.6" specular="0.2 0.2 0.2" pos="0 0 4" dir="0 0 -1" />
    <geom name="ground" type="plane" pos="0 0 -0.1" size="100 100 0.001" quat="1 0 0 0" material="matplane" condim="3" conaffinity="15" />
    <camera name="fixed" pos="0 -3.0 0.5678935698520802" xyaxes="1 0 0 0 0 1" />
    <camera name="track" mode="trackcom" pos="0 -3.0 0.5678935698520802" xyaxes="1 0 0 0 0 1" />
    <body name="root" pos="-1 0 0.05" quat="1 0 0 0">
      <!-- <freejoint name="root" /> -->
      <site name="imu" size="0.01" pos="0 0 0" />
      <geom type="mesh" rgba="0.2 0.2 0.2 1" mesh="mounting_plate" contype="1" conaffinity="0" density="0" group="1" class="visualgeom" />
      <geom type="mesh" rgba="0.2 0.2 0.2 1" mesh="mounting_plate" />
      <geom pos="0 0 0.005" quat="1 0 0 0" type="mesh" rgba="1 0.3 0.3 1" mesh="base_fixed_part" contype="1" conaffinity="0" density="0" group="1" class="visualgeom" />
      <geom type="mesh" rgba="1 0.3 0.3 1" mesh="base_fixed_part" pos="0 0 0.005" quat="1 0 0 0" />
      <body name="crane_x7_shoulder_revolute_part_link" pos="0 0 0.041">
        <inertial pos="0.000243 -0.000105 0.047" quat="0.999919 0.00366383 -0.00493351 -0.0111249" mass="0.253" diaginertia="0.00017901 0.000176003 8.95867e-05" />
        <joint name="crane_x7_shoulder_fixed_part_pan_joint" pos="0 0 0" axis="0 0 1" range="-2.74017 2.74017" actuatorfrcrange="-10 10" damping="1e-06" frictionloss="0.2" />
        <geom size="0.0334 0.01475" pos="0 0 0.0296" type="cylinder" rgba="0.95 0.95 0.95 1" contype="1" conaffinity="0" density="0" group="1" class="visualgeom" />
        <!-- <geom type="cylinder" rgba="0.95 0.95 0.95 1" pos="0 0 0.0296" /> -->
        <geom size="0.034 0.02455" pos="0 0 0.064" quat="0.707107 0.707106 0 0" type="cylinder" rgba="0.95 0.95 0.95 1" contype="1" conaffinity="0" density="0" group="1" class="visualgeom" />
        <!-- <geom type="cylinder" rgba="0.95 0.95 0.95 1" pos="0 0 0.064" quat="0.707107 0.707106 0 0" /> -->
        <body name="crane_x7_upper_arm_fixed_part_link" pos="0 0 0.064">
          <inertial pos="2.9315e-05 1.79674e-05 0.0323413" quat="0.70765 0.706547 0.00347624 -0.00329379" mass="0.143816" diaginertia="0.000185901 0.000143297 0.000106301" />
          <joint name="crane_x7_shoulder_revolute_part_tilt_joint" pos="0 0 0" axis="0 -1 0" range="-1.6057 1.6057" actuatorfrcrange="-10 10" damping="1e-06" frictionloss="0.2" />
          <geom quat="0.707107 0.707106 0 0" type="mesh" rgba="0.95 0.95 0.95 1" mesh="rotating_link_type_1_fixed_part" contype="1" conaffinity="0" density="0" group="1" class="visualgeom" />
          <geom type="mesh" rgba="0.95 0.95 0.95 1" mesh="rotating_link_type_1_fixed_part" quat="0.707107 0.707106 0 0" />
          <geom pos="0 0.0316 0" quat="0.707107 -0.707106 0 0" type="mesh" rgba="1 0.3 0.3 1" mesh="joint_cover" contype="1" conaffinity="0" density="0" group="1" class="visualgeom" />
          <geom type="mesh" rgba="1 0.3 0.3 1" mesh="joint_cover" pos="0 0.0316 0" quat="0.707107 -0.707106 0 0" />
          <geom pos="0 -0.0316 0" quat="0.707107 0.707106 0 0" type="mesh" rgba="1 0.3 0.3 1" mesh="joint_cover" contype="1" conaffinity="0" density="0" group="1" class="visualgeom" />
          <geom type="mesh" rgba="1 0.3 0.3 1" mesh="joint_cover" pos="0 -0.0316 0" quat="0.707107 0.707106 0 0" />
          <body name="crane_x7_upper_arm_revolute_part_link" pos="0 0 0.065">
            <inertial pos="-0.0137 -8.1e-05 0.0952" quat="0.711007 0.00874971 0.00712763 0.703094" mass="0.321" diaginertia="0.00188002 0.00182083 0.000158153" />
            <joint name="crane_x7_upper_arm_revolute_part_twist_joint" pos="0 0 0" axis="0 0 1" range="-2.74017 2.74017" actuatorfrcrange="-4 4" damping="1e-06" frictionloss="0.2" />
            <geom type="mesh" rgba="0.95 0.95 0.95 1" mesh="rotating_link_type_1_revolute_part" contype="1" conaffinity="0" density="0" group="1" class="visualgeom" />
            <geom type="mesh" rgba="0.95 0.95 0.95 1" mesh="rotating_link_type_1_revolute_part" />
            <body name="crane_x7_lower_arm_fixed_part_link" pos="0 0 0.185">
              <inertial pos="-0.00907065 6.18234e-05 0.0776656" quat="0.707954 0.701554 -0.0608721 0.0540158" mass="0.229816" diaginertia="0.000544972 0.000508975 0.000164863" />
              <joint name="crane_x7_upper_arm_revolute_part_rotate_joint" pos="0 0 0" axis="0 -1 0" range="-2.80998 1.74533e-05" actuatorfrcrange="-4 4" damping="1e-06" frictionloss="0.2" />
              <geom pos="0 0 0" quat="0.707107 0.707106 0 0" type="mesh" rgba="0.95 0.95 0.95 1" mesh="rotating_link_type_2_fixed_part" contype="1" conaffinity="0" density="0" group="1" class="visualgeom" />
              <geom type="mesh" rgba="0.95 0.95 0.95 1" mesh="rotating_link_type_2_fixed_part" pos="0 0 0" quat="0.707107 0.707106 0 0" />
              <geom pos="0 0.025 0" quat="0.707107 -0.707106 0 0" type="mesh" rgba="1 0.3 0.3 1" mesh="joint_cover" contype="1" conaffinity="0" density="0" group="1" class="visualgeom" />
              <geom type="mesh" rgba="1 0.3 0.3 1" mesh="joint_cover" pos="0 0.025 0" quat="0.707107 -0.707106 0 0" />
              <geom pos="0 -0.025 0" quat="0.707107 0.707106 0 0" type="mesh" rgba="1 0.3 0.3 1" mesh="joint_cover" contype="1" conaffinity="0" density="0" group="1" class="visualgeom" />
              <geom type="mesh" rgba="1 0.3 0.3 1" mesh="joint_cover" pos="0 -0.025 0" quat="0.707107 0.707106 0 0" />
              <body name="crane_x7_lower_arm_revolute_part_link" pos="0 0 0.121">
                <inertial pos="-8.38573e-05 0.00046142 0.0637449" quat="0.998796 -0.0489937 0.00125063 0.00225264" mass="0.20726" diaginertia="0.000290754 0.000259098 8.61531e-05" />
                <joint name="crane_x7_lower_arm_fixed_part_joint" pos="0 0 0" axis="0 0 1" range="-2.74017 2.74017" actuatorfrcrange="-4 4" damping="1e-06" frictionloss="0.2" />
                <geom type="mesh" rgba="0.95 0.95 0.95 1" mesh="rotating_link_type_2_revolute_part" contype="1" conaffinity="0" density="0" group="1" class="visualgeom" />
                <geom type="mesh" rgba="0.95 0.95 0.95 1" mesh="rotating_link_type_2_revolute_part" />
                <geom pos="0 0.0345 0.095" quat="0.500001 -0.5 0.5 0.499999" type="mesh" rgba="0.2 0.2 0.2 1" mesh="rtcorp_logo_name" contype="1" conaffinity="0" density="0" group="1" class="visualgeom" />
                <geom type="mesh" rgba="0.2 0.2 0.2 1" mesh="rtcorp_logo_name" pos="0 0.0345 0.095" quat="0.500001 -0.5 0.5 0.499999" />
                <geom pos="0 0.0345 0.132" quat="0.500001 -0.5 0.5 0.499999" type="mesh" rgba="1 0.3 0.3 1" mesh="rtcorp_logo_rabbit" contype="1" conaffinity="0" density="0" group="1" class="visualgeom" />
                <geom type="mesh" rgba="1 0.3 0.3 1" mesh="rtcorp_logo_rabbit" pos="0 0.0345 0.132" quat="0.500001 -0.5 0.5 0.499999" />
                <geom pos="0 -0.0345 0.104" quat="0.500001 0.5 -0.5 0.499999" type="mesh" rgba="0.2 0.2 0.2 1" mesh="rtcorp_logo_name" contype="1" conaffinity="0" density="0" group="1" class="visualgeom" />
                <geom type="mesh" rgba="0.2 0.2 0.2 1" mesh="rtcorp_logo_name" pos="0 -0.0345 0.104" quat="0.500001 0.5 -0.5 0.499999" />
                <geom pos="0 -0.0345 0.065" quat="0.500001 0.5 -0.5 0.499999" type="mesh" rgba="1 0.3 0.3 1" mesh="rtcorp_logo_rabbit" contype="1" conaffinity="0" density="0" group="1" class="visualgeom" />
                <geom type="mesh" rgba="1 0.3 0.3 1" mesh="rtcorp_logo_rabbit" pos="0 -0.0345 0.065" quat="0.500001 0.5 -0.5 0.499999" />
                <body name="crane_x7_wrist_link" pos="0 0 0.129">
                  <inertial pos="0.0061 0.000826 -0.00355" quat="-0.0636037 0.712374 0.0304283 0.69825" mass="0.14" diaginertia="7.35371e-05 6.16647e-05 3.96983e-05" />
                  <joint name="crane_x7_lower_arm_revolute_part_joint" pos="0 0 0" axis="0 -1 0" range="-1.5708 1.5708" actuatorfrcrange="-4 4" damping="1e-06" frictionloss="0.2" />
                  <geom quat="0.707107 0.707106 0 0" type="mesh" rgba="0.95 0.95 0.95 1" mesh="wrist" contype="1" conaffinity="0" density="0" group="1" class="visualgeom" />
                  <geom type="mesh" rgba="0.95 0.95 0.95 1" mesh="wrist" quat="0.707107 0.707106 0 0" />
                  <body name="crane_x7_gripper_base_link" pos="0 0 0.019">
                    <inertial pos="0.000108 -0.00103 0.0208" quat="0.0785654 0.710177 0.0883506 0.694025" mass="0.121" diaginertia="4.29993e-05 4.13081e-05 3.19926e-05" />
                    <joint name="crane_x7_wrist_joint" pos="0 0 0" axis="0 0 1" range="-2.9147 2.9147" actuatorfrcrange="-4 4" damping="1e-06" frictionloss="0.2" />
                    <geom type="mesh" rgba="1 0.3 0.3 1" mesh="wide_two_finger_gripper_actuator" contype="1" conaffinity="0" density="0" group="1" class="visualgeom" />
                    <geom type="mesh" rgba="1 0.3 0.3 1" mesh="wide_two_finger_gripper_actuator" />
                    <body name="crane_x7_gripper_finger_a_link" pos="-0.012 0 0.024">
                      <inertial pos="-0.00265 0.00354 0.0269" quat="0.81737 0.575529 0.000867923 -0.0259175" mass="0.0158" diaginertia="1.01113e-05 6.42734e-06 4.75141e-06" />
                      <joint name="crane_x7_gripper_finger_a_joint" pos="0 0 0" axis="0 -1 0" range="-0.0872665 1.5708" actuatorfrcrange="-4 4" damping="1e-06" frictionloss="0.8" />
                      <geom quat="0.707107 0.707106 0 0" type="mesh" rgba="1 0.3 0.3 1" mesh="wide_two_finger_gripper_finger_a" contype="1" conaffinity="0" density="0" group="1" class="visualgeom" />
                      <geom type="mesh" rgba="1 0.3 0.3 1" mesh="wide_two_finger_gripper_finger_a" quat="0.707107 0.707106 0 0" />
                    </body>
                    <body name="crane_x7_gripper_finger_b_link" pos="0.012 0 0.024">
                      <inertial pos="0.00301 0.00285 0.0309" quat="0.851768 0.521016 0.0159772 0.0527074" mass="0.0139" diaginertia="7.52043e-06 4.48055e-06 3.93902e-06" />
                      <joint name="crane_x7_gripper_finger_b_joint" pos="0 0 0" axis="0 1 0" range="-0.0872665 1.5708" actuatorfrcrange="-4 4" damping="1e-06" frictionloss="0.8" />
                      <geom quat="0.707107 0.707106 0 0" type="mesh" rgba="1 0.3 0.3 1" mesh="wide_two_finger_gripper_finger_b" contype="1" conaffinity="0" density="0" group="1" class="visualgeom" />
                      <geom type="mesh" rgba="1 0.3 0.3 1" mesh="wide_two_finger_gripper_finger_b" quat="0.707107 0.707106 0 0" />
                    </body>
                    <body name="racket" pos="0 0 0">
                      <geom name="racket_handle" type="cylinder" size="0.01 0.1" pos="0 0 0" rgba="1 0.3 0.3 1" />
                      <geom name="racket_head" type="cylinder" size="0.05 0.01" pos="0 0 0.1" rgba="1 0.3 0.3 1" />
                      <site name="ee_site" pos="0 0 0" size="0.01" rgba="0 1 0 1" />
                    </body>
                  </body>
                </body>
              </body>
            </body>
          </body>
        </body>
      </body>
    </body>
  </worldbody>

  <actuator>
    <motor name="crane_x7_shoulder_fixed_part_pan_joint" joint="crane_x7_shoulder_fixed_part_pan_joint" ctrllimited="true" ctrlrange="-10 10" gear="100" />
    <motor name="crane_x7_shoulder_revolute_part_tilt_joint" joint="crane_x7_shoulder_revolute_part_tilt_joint" ctrllimited="true" ctrlrange="-10 10" gear="100" />
    <motor name="crane_x7_upper_arm_revolute_part_twist_joint" joint="crane_x7_upper_arm_revolute_part_twist_joint" ctrllimited="true" ctrlrange="-4 4" gear="100" />
    <motor name="crane_x7_upper_arm_revolute_part_rotate_joint" joint="crane_x7_upper_arm_revolute_part_rotate_joint" ctrllimited="true" ctrlrange="-4 4" gear="100" />
    <motor name="crane_x7_lower_arm_fixed_part_joint" joint="crane_x7_lower_arm_fixed_part_joint" ctrllimited="true" ctrlrange="-4 4" gear="100" />
    <motor name="crane_x7_lower_arm_revolute_part_joint" joint="crane_x7_lower_arm_revolute_part_joint" ctrllimited="true" ctrlrange="-4 4" gear="100" />
    <motor name="crane_x7_wrist_joint" joint="crane_x7_wrist_joint" ctrllimited="true" ctrlrange="-4 4" gear="100" />
    <motor name="crane_x7_gripper_finger_a_joint" joint="crane_x7_gripper_finger_a_joint" ctrllimited="true" ctrlrange="-4 4" gear="100" />
    <motor name="crane_x7_gripper_finger_b_joint" joint="crane_x7_gripper_finger_b_joint" ctrllimited="true" ctrlrange="-4 4" gear="100" />
  </actuator>

  <sensor>
    <actuatorpos name="crane_x7_shoulder_fixed_part_pan_joint_p" actuator="crane_x7_shoulder_fixed_part_pan_joint" />
    <actuatorvel name="crane_x7_shoulder_fixed_part_pan_joint_v" actuator="crane_x7_shoulder_fixed_part_pan_joint" />
    <actuatorfrc name="crane_x7_shoulder_fixed_part_pan_joint_f" actuator="crane_x7_shoulder_fixed_part_pan_joint" noise="0.001" />
    <actuatorpos name="crane_x7_shoulder_revolute_part_tilt_joint_p" actuator="crane_x7_shoulder_revolute_part_tilt_joint" />
    <actuatorvel name="crane_x7_shoulder_revolute_part_tilt_joint_v" actuator="crane_x7_shoulder_revolute_part_tilt_joint" />
    <actuatorfrc name="crane_x7_shoulder_revolute_part_tilt_joint_f" actuator="crane_x7_shoulder_revolute_part_tilt_joint" noise="0.001" />
    <actuatorpos name="crane_x7_upper_arm_revolute_part_twist_joint_p" actuator="crane_x7_upper_arm_revolute_part_twist_joint" />
    <actuatorvel name="crane_x7_upper_arm_revolute_part_twist_joint_v" actuator="crane_x7_upper_arm_revolute_part_twist_joint" />
    <actuatorfrc name="crane_x7_upper_arm_revolute_part_twist_joint_f" actuator="crane_x7_upper_arm_revolute_part_twist_joint" noise="0.001" />
    <actuatorpos name="crane_x7_upper_arm_revolute_part_rotate_joint_p" actuator="crane_x7_upper_arm_revolute_part_rotate_joint" />
    <actuatorvel name="crane_x7_upper_arm_revolute_part_rotate_joint_v" actuator="crane_x7_upper_arm_revolute_part_rotate_joint" />
    <actuatorfrc name="crane_x7_upper_arm_revolute_part_rotate_joint_f" actuator="crane_x7_upper_arm_revolute_part_rotate_joint" noise="0.001" />
    <actuatorpos name="crane_x7_lower_arm_fixed_part_joint_p" actuator="crane_x7_lower_arm_fixed_part_joint" />
    <actuatorvel name="crane_x7_lower_arm_fixed_part_joint_v" actuator="crane_x7_lower_arm_fixed_part_joint" />
    <actuatorfrc name="crane_x7_lower_arm_fixed_part_joint_f" actuator="crane_x7_lower_arm_fixed_part_joint" noise="0.001" />
    <actuatorpos name="crane_x7_lower_arm_revolute_part_joint_p" actuator="crane_x7_lower_arm_revolute_part_joint" />
    <actuatorvel name="crane_x7_lower_arm_revolute_part_joint_v" actuator="crane_x7_lower_arm_revolute_part_joint" />
    <actuatorfrc name="crane_x7_lower_arm_revolute_part_joint_f" actuator="crane_x7_lower_arm_revolute_part_joint" noise="0.001" />
    <actuatorpos name="crane_x7_wrist_joint_p" actuator="crane_x7_wrist_joint" />
    <actuatorvel name="crane_x7_wrist_joint_v" actuator="crane_x7_wrist_joint" />
    <actuatorfrc name="crane_x7_wrist_joint_f" actuator="crane_x7_wrist_joint" noise="0.001" />
    <actuatorpos name="crane_x7_gripper_finger_a_joint_p" actuator="crane_x7_gripper_finger_a_joint" />
    <actuatorvel name="crane_x7_gripper_finger_a_joint_v" actuator="crane_x7_gripper_finger_a_joint" />
    <actuatorfrc name="crane_x7_gripper_finger_a_joint_f" actuator="crane_x7_gripper_finger_a_joint" noise="0.001" />
    <actuatorpos name="crane_x7_gripper_finger_b_joint_p" actuator="crane_x7_gripper_finger_b_joint" />
    <actuatorvel name="crane_x7_gripper_finger_b_joint_v" actuator="crane_x7_gripper_finger_b_joint" />
    <actuatorfrc name="crane_x7_gripper_finger_b_joint_f" actuator="crane_x7_gripper_finger_b_joint" noise="0.001" />
    <framequat name="orientation" objtype="site" noise="0.001" objname="imu" />
    <gyro name="angular-velocity" site="imu" noise="0.005" cutoff="34.9" />
  </sensor>
</mujoco>
